Workbook

Sheet SHEET 2
A1: # | B1: PROVINCE | C1: NUMBER OF WARDS | D1: TOTAL NUMBER OF WARDS WITH 200 OR MORE VALID MEMBERSHIP | E1: TOTAL NUMBER OF WARDS WITH LESS THAN 200 VALID MEMBERSHIP | F1: PERCENTAGE % TOWARDS SRPA
A2: 1. | B2: Eastern Cape | C2: =Sheet1!B48 -> 710 | D2: =Sheet1!D48 -> 637 | E2: =Sheet1!E48 -> 73 | F2: =D2/C2 -> 0.8971831
A3: 2. | B3: Free State | C3: =Sheet1!B72 -> 319 | D3: =Sheet1!D72 -> 287 | E3: =Sheet1!E72 -> 32 | F3: =D3/C3 -> 0.89968652
A4: 3. | B4: Gauteng | C4: =Sheet1!B101 -> 529 | D4: =Sheet1!D101 -> 514 | E4: =Sheet1!E101 -> 15 | F4: =D4/C4 -> 0.97164461
A5: 4. | B5: KwaZulu-Natal | C5: =Sheet1!B160 -> 901 | D5: =Sheet1!D160 -> 684 | E5: =Sheet1!E160 -> 217 | F5: =D5/C5 -> 0.75915649
A6: 5. | B6: Limpopo | C6: =Sheet1!B188 -> 568 | D6: =Sheet1!D188 -> 559 | E6: =Sheet1!E188 -> 9 | F6: =D6/C6 -> 0.98415493
A7: 6. | B7: Mpumalanga | C7: =Sheet1!B209 -> 400 | D7: =Sheet1!D209 -> 387 | E7: =Sheet1!E209 -> 13 | F7: =D7/C7 -> 0.9675
A8: 7. | B8: North West | C8: =Sheet1!B230 -> 403 | D8: =Sheet1!D230 -> 382 | E8: =Sheet1!E230 -> 21 | F8: =D8/C8 -> 0.94789082
A9: 8. | B9: Northern Cape | C9: =Sheet1!B252 -> 232 | D9: =Sheet1!D252 -> 143 | E9: =Sheet1!E252 -> 89 | F9: =D9/C9 -> 0.61637931
A10: 9. | B10: Western Cape | C10: =Sheet1!B286 -> 406 | D10: =Sheet1!D286 -> 296 | E10: =Sheet1!E286 -> 110 | F10: =D10/C10 -> 0.72906404
A11: TOTAL | C11: =SUM(C2:C10) -> 4468 | D11: =SUM(D2:D10) -> 3889 | E11: =SUM(E2:E10) -> 579 | F11: =D11/C11 -> 0.87041182
A15: # | B15: PROVINCE | C15: NUMBER OF WARDS | D15: TOTAL NUMBER OF WARDS WITH 200 OR MORE VALID MEMBERSHIP | E15: TOTAL NUMBER OF WARDS WITH 150 -199 VALID MEMBERSHIP | F15: PERCENTAGE % | G15: PERCENTAGE %
A16: 1. | B16: Eastern Cape | C16: 710 | D16: 297 | E16: 109 | F16: =D16/C16 -> 0.41830986 | G16: =E16/C16 -> 0.15352113
A17: 2. | B17: Free State | C17: 319 | D17: 251 | E17: 13 | F17: =D17/C17 -> 0.78683386 | G17: =E17/C17 -> 0.040752351
A18: 3. | B18: Gauteng | C18: 529 | D18: 509 | E18: 3 | F18: =D18/C18 -> 0.96219282 | G18: =E18/C18 -> 0.0056710775
A19: 4. | B19: KwaZulu-Natal | C19: 901 | D19: 262 | E19: 113 | F19: =D19/C19 -> 0.29078801 | G19: =E19/C19 -> 0.1254162
A20: 5. | B20: Limpopo | C20: 568 | D20: 451 | E20: 43 | F20: =D20/C20 -> 0.79401408 | G20: =E20/C20 -> 0.075704225
A21: 6. | B21: Mpumalanga | C21: 400 | D21: 364 | E21: 12 | F21: =D21/C21 -> 0.91 | G21: =E21/C21 -> 0.03
A22: 7. | B22: North West | C22: 403 | D22: 275 | E22: 39 | F22: =D22/C22 -> 0.68238213 | G22: =E22/C22 -> 0.096774194
A23: 8. | B23: Northern Cape | C23: 239 | D23: 98 | E23: 7 | F23: =D23/C23 -> 0.41004184 | G23: =E23/C23 -> 0.029288703
A24: 9. | B24: Western Cape | C24: 399 | D24: 171 | E24: 63 | F24: =D24/C24 -> 0.42857143 | G24: =E24/C24 -> 0.15789474
A25: TOTAL | C25: =SUM(C16:C24) -> 4468 | D25: =SUM(D16:D24) -> 2678 | E25: =SUM(E16:E24) -> 402 | F25: =D25/C25 -> 0.59937332 | G25: =E25/C25 -> 0.089973142

Sheet Sheet1
A1: MUNICIPALITY/ DISTRICTS | B1: NUMBER OF IEC WARDS | D1: TOTAL NUMBER OF WARDS WITH 200 OR MORE VALID MEMBERSHIP | E1: TOTAL NUMBER OF WARDS WITH LESS THAN 200 VALID MEMBERSHIP | F1: PERCENTAGE % TOWARDS BPA/BGA | G1: DEPLOYEE
A2: BUF-Duncan Village | B2: 8 | D2: 8 | E2: =B2-D2 -> 0 | F2: =D2/B2 -> 1
A3: BUF-East London | B3: 17 | D3: 16 | E3: =B3-D3 -> 1 | F3: =D3/B3 -> 0.94117647
A4: BUF-King Williams Town | B4: 13 | D4: 13 | E4: =B4-D4 -> 0 | F4: =D4/B4 -> 1
A5: BUF-Mdantsane | B5: 12 | D5: 12 | E5: =B5-D5 -> 0 | F5: =D5/B5 -> 1
A6: TOTAL | B6: =SUM(B2:B5) -> 50 | D6: =SUM(D2:D5) -> 49 | E6: =SUM(E2:E5) -> 1 | F6: =D6/B6 -> 0.98
A7: Dr. Beyers Naude / Blue Crane Route | B7: 12 + 6 = 18 | C7: 18 | D7: 4 | E7: =C7-D7 -> 14 | F7: =D7/C7 -> 0.22222222
A8: Kouga / Kou-Kamma | B8: 15 + 6 = 21 | C8: 21 | D8: 2 | E8: =C8-D8 -> 19 | F8: =D8/C8 -> 0.095238095
A9: Makana | B9: 14 | D9: 14 | E9: =B9-D9 -> 0 | F9: =D9/B9 -> 1
A10: Ndlambe | B10: 10 | D10: 8 | E10: =B10-D10 -> 2 | F10: 0.9
A11: Sundays River Valley | B11: 8 | D11: 2 | E11: =B11-D11 -> 6 | F11: =D11/B11 -> 0.25
A12: TOTAL | B12: =14+10+8+18+21 -> 71 | D12: =SUM(D7:D11) -> 30 | E12: =SUM(E7:E11) -> 41 | F12: =D12/B12 -> 0.42253521
A13: Amahlathi / Great Kei | B13: 15 + 7 = 22 | C13: 22 | D13: 22 | E13: =C13-D13 -> 0 | F13: =D13/C13 -> 1
A14: Mbashe | B14: 32 | D14: 29 | E14: =B14-D14 -> 3 | F14: =D14/B14 -> 0.90625
A15: Mnquma | B15: 32 | D15: 32 | E15: =B15-D15 -> 0 | F15: =D15/B15 -> 1
A16: Ngqushwa | B16: 12 | D16: 12 | E16: =B16-D16 -> 0 | F16: =D16/B16 -> 1
A17: Raymond Mhlaba | B17: 23 | D17: 21 | E17: =B17-D17 -> 2 | F17: =D17/B17 -> 0.91304348
A18: TOTAL | B18: =22+32+32+12+23 -> 121 | D18: =SUM(D13:D17) -> 116 | E18: =SUM(E13:E17) -> 5 | F18: =D18/B18 -> 0.95867769
A19: Inxuba Yethemba | B19: 9 | D19: 9 | E19: =B19-D19 -> 0 | F19: =D19/B19 -> 1
A20: Intsika Yethu | B20: 21 | D20: 20 | E20: =B20-D20 -> 1 | F20: =D20/B20 -> 0.95238095
A21: Emalahleni | B21: 17 | D21: 16 | E21: =B21-D21 -> 1 | F21: =D21/B21 -> 0.94117647
A22: Dr AB Xuma | B22: 20 | D22: 19 | E22: =B22-D22 -> 1 | F22: =D22/B22 -> 0.95
A23: Sakhisizwe | B23: 9 | D23: 7 | E23: =B23-D23 -> 2 | F23: =D23/B23 -> 0.77777778
A24: Enoch Mgijima | B24: 34 | D24: 34 | E24: =B24-D24 -> 0 | F24: =D24/B24 -> 1
A25: TOTAL | B25: =SUM(B19:B24) -> 110 | D25: =SUM(D19:D24) -> 105 | E25: =SUM(E19:E24) -> 5 | F25: =D25/B25 -> 0.95454545
A26: Elundini | B26: 17 | D26: 5 | E26: =B26-D26 -> 12 | F26: =D26/B26 -> 0.29411765
A27: Senqu | B27: 17 | D27: 17 | E27: =B27-D27 -> 0 | F27: =D27/B27 -> 1
A28: Walter Sisulu | B28: 11 | D28: 11 | E28: =B28-D28 -> 0 | F28: =D28/B28 -> 1
A29: TOTAL | B29: =SUM(B26:B28) -> 45 | D29: =SUM(D26:D28) -> 33 | E29: =SUM(E26:E28) -> 12 | F29: =D29/B29 -> 0.73333333
A30: Ngquza Hill | B30: 32 | D30: 32 | E30: =B30-D30 -> 0 | F30: =D30/B30 -> 1
A31: Port St Johns | B31: 20 | D31: 18 | E31: =B31-D31 -> 2 | F31: =D31/B31 -> 0.9
A32: Mhlontlo | B32: 26 | D32: 26 | E32: =B32-D32 -> 0 | F32: =D32/B32 -> 1
A33: King Sabata Dalindyebo | B33: 37 | D33: 37 | E33: =B33-D33 -> 0 | F33: =D33/B33 -> 1
A34: Nyandeni | B34: 32 | D34: 29 | E34: =B34-D34 -> 3 | F34: =D34/B34 -> 0.90625
A35: TOTAL | B35: =SUM(B30:B34) -> 147 | D35: =SUM(D30:D34) -> 142 | E35: =SUM(E30:E34) -> 5 | F35: =D35/B35 -> 0.96598639
A36: Matatiele | B36: 27 | D36: 26 | E36: =B36-D36 -> 1 | F36: =D36/B36 -> 0.96296296
A37: Umzimvubu | B37: 28 | D37: 28 | E37: =B37-D37 -> 0 | F37: =D37/B37 -> 1
A38: Winnie Madikizela Mandela | B38: 32 | D38: 30 | E38: =B38-D38 -> 2 | F38: =D38/B38 -> 0.9375
A39: Ntabankulu | B39: 19 | D39: 18 | E39: =B39-D39 -> 1 | F39: =D39/B39 -> 0.94736842
A40: TOTAL | B40: =SUM(B36:B39) -> 106 | D40: =SUM(D36:D39) -> 102 | E40: =SUM(E36:E39) -> 4 | F40: =D40/B40 -> 0.96226415
...
