Workbook

Sheet Sheet4
A1: MUNICIPALITY | B1: NUMBER OF IEC WARDS | D1: NUMBER OF BRANCHES CONVENED | E1: NUMBER OF BRANCHES NOT CONVENED | F1: NUMBER OF BRANCHES PASSED AUDIT | G1: NUMBER OF BRANCHES FAILED AUDIT | H1: PERCENTAGE % TOWARDS 1ST SRPA
A2: Matatiele | B2: 27 | D2: =F2+G2 | E2: =B2-D2 | F2: 9 | G2: 0 | H2: =F2/B2
A3: Mbizana | B3: 32 | D3: =F3+G3 | E3: =B3-D3 | F3: 3 | G3: 0 | H3: =F3/B3
A4: Ntabankulu | B4: 19 | D4: =F4+G4 | E4: =B4-D4 | F4: 4 | G4: 0 | H4: =F4/B4
A5: Umzimvubu | B5: 28 | D5: =F5+G5 | E5: =B5-D5 | F5: 8 | G5: 0 | H5: =F5/B5
A6: TOTAL | B6: =SUM(B2:B5) | D6: =SUM(D2:D5) | E6: =SUM(E2:E5) | F6: =SUM(F2:F5) | G6: =SUM(G2:G5) | H6: =F6/B6
A7: Amahlathi / Great Kei | B7: 15 + 7 = 22 | C7: 22 | D7: =F7+G7 | E7: =C7-D7 | F7: 3 | G7: 0 | H7: =F7/C7
A8: Mbhashe | B8: 32 | D8: =F8+G8 | E8: =B8-D8 | F8: 6 | G8: 0 | H8: =F8/B8
A9: Mnquma | B9: 32 | D9: =F9+G9 | E9: =B9-D9 | F9: 4 | G9: 0 | H9: =F9/B9
A10: Ngqushwa | B10: 12 | D10: =F10+G10 | E10: =B10-D10 | F10: 2 | G10: 0 | H10: =F10/B10
A11: Raymond Mhlaba | B11: 23 | D11: =F11+G11 | E11: =B11-D11 | F11: 4 | G11: 0 | H11: =F11/B11
A12: TOTAL | B12: =SUM(B7:B11) | D12: =SUM(D7:D11) | E12: =SUM(E7:E11) | F12: =SUM(F7:F11) | G12: =SUM(G7:G11) | H12: =F12/B12
A13: BUF - East London | B13: 17 | D13: =F13+G13 | E13: =B13-D13 | F13: 13 | G13: 0 | H13: =F13/B13
A14: BUF - King Williams Town | B14: 13 | D14: =F14+G14 | E14: =B14-D14 | F14: 6 | G14: 0 | H14: =F14/B14
A15: BUF - Mdantsane | B15: 12 | D15: =F15+G15 | E15: =B15-D15 | F15: 11 | G15: 0 | H15: =F15/B15
A16: BUF-Duncan Village | B16: 8 | D16: =F16+G16 | E16: =B16-D16 | F16: 3 | G16: 0 | H16: =F16/B16
A17: TOTAL | B17: =SUM(B13:B16) | D17: =SUM(D13:D16) | E17: =SUM(E13:E16) | F17: =SUM(F13:F16) | G17: =SUM(G13:G16) | H17: =F17/B17
A18: Emalahleni | B18: 17 | D18: =F18+G18 | E18: =B18-D18 | F18: 1 | G18: 0 | H18: =F18/B18
A19: Engcobo | B19: 20 | D19: =F19+G19 | E19: =B19-D19 | F19: 1 | G19: 0 | H19: =F19/B19
A20: Enoch Mgijima | B20: 34 | D20: =F20+G20 | E20: =B20-D20 | F20: 5 | G20: 0 | H20: =F20/B20
A21: Intsika Yethu | B21: 21 | D21: =F21+G21 | E21: =B21-D21 | F21: 4 | G21: 0 | H21: =F21/B21
A22: Inxuba Yethemba | B22: 9 | D22: =F22+G22 | E22: =B22-D22 | F22: 0 | G22: 0 | H22: =F22/B22
A23: Sakhisizwe | B23: 9 | D23: =F23+G23 | E23: =B23-D23 | F23: 1 | G23: 0 | H23: =F23/B23
A24: TOTAL | B24: =SUM(B18:B23) | D24: =SUM(D18:D23) | E24: =SUM(E18:E23) | F24: =SUM(F18:F23) | G24: =SUM(G18:G23) | H24: =F24/B24
A25: Elundini | B25: 17 | D25: =F25+G25 | E25: =B25-D25 | F25: 1 | G25: 0 | H25: =F25/B25
A26: Senqu | B26: 17 | D26: =F26+G26 | E26: =B26-D26 | F26: 3 | G26: 0 | H26: =F26/B26
A27: Walter Sisulu | B27: 11 | D27: =F27+G27 | E27: =B27-D27 | F27: 3 | G27: 0 | H27: =F27/B27
A28: TOTAL | B28: =SUM(B25:B27) | D28: =SUM(D25:D27) | E28: =SUM(E25:E27) | F28: =SUM(F25:F27) | G28: =SUM(G25:G27) | H28: =F28/B28
A29: NMA - Champion Galela | B29: 9 | D29: =F29+G29 | E29: =B29-D29 | F29: 8 | G29: 0 | H29: =F29/B29
A30: NMA - Govan Mbeki | B30: 10 | D30: =F30+G30 | E30: =B30-D30 | F30: 6 | G30: 0 | H30: =F30/B30
A31: NMA - Lillian Diedericks | B31: 10 | D31: =F31+G31 | E31: =B31-D31 | F31: 3 | G31: 0 | H31: =F31/B31
A32: NMA - Molly Blackburn | B32: 11 | D32: =F32+G32 | E32: =B32-D32 | F32: 5 | G32: 0 | H32: =F32/B32
A33: NMA - Zola Nqini | B33: 11 | D33: =F33+G33 | E33: =B33-D33 | F33: 6 | G33: 0 | H33: =F33/B33
A34: NMA-Alex Matikama | B34: 8 | D34: =F34+G34 | E34: =B34-D34 | F34: 5 | G34: 0 | H34: =F34/B34
A35: NMA-Alex Matikanca | B35: 1 | D35: =F35+G35 | E35: =B35-D35 | F35: 1 | G35: 0 | H35: =F35/B35
A36: TOTAL | B36: =SUM(B29:B35) | D36: =SUM(D29:D35) | E36: =SUM(E29:E35) | F36: =SUM(F29:F35) | G36: =SUM(G29:G35) | H36: =F36/B36
A37: Ingquza Hill | B37: 32 | D37: =F37+G37 | E37: =B37-D37 | F37: 7 | G37: 0 | H37: =F37/B37
A38: King Sabata Dalindyebo | B38: 37 | D38: =F38+G38 | E38: =B38-D38 | F38: 12 | G38: 0 | H38: =F38/B38
A39: Mhlontlo | B39: 26 | D39: =F39+G39 | E39: =B39-D39 | F39: 6 | G39: 0 | H39: =F39/B39
A40: Nyandeni | B40: 32 | D40: =F40+G40 | E40: =B40-D40 | F40: 20 | G40: 0 | H40: =F40/B40
...

Sheet Sheet1
A1: # | B1: PROVINCE | C1: NUMBER OF IEC WARDS | D1: TOTAL NUMBER OF REGISTERS ISSUED | E1: NUMBER OF BRANCHES CONVENED BPA/BGA | F1: NUMBER OF BRANCHES NOT CONVENED BPA/BGA | G1: NUMBER OF BRANCHES PASSED AUDIT | H1: NUMBER OF BRANCHES FAILED AUDIT | I1: NUMBER OF BRANCHES CURRENTLY IN AUDIT | K1: NUMBER OF BRANCHES CONVENED BPA/BGA FROM PREVIOUS WAR COUNCIL | L1: PERCENTAGE % TOWARDS 1ST SRPA
A2: 1 | B2: Eastern Cape | C2: =Sheet4!B49 | D2: 0 | E2: =Sheet4!D49 | F2: =Sheet4!E49 | G2: =Sheet4!F49 | H2: =Sheet4!G49 | I2: 0 | K2: 0 | L2: =Sheet4!H49
A3: 2 | B3: Free State | C3: =Sheet4!B73 | D3: 0 | E3: =Sheet4!D73 | F3: =Sheet4!E73 | G3: =Sheet4!F73 | H3: =Sheet4!G73 | I3: 0 | K3: 0 | L3: =Sheet4!H73
A4: 3 | B4: Gauteng | C4: =Sheet4!B102 | D4: 0 | E4: =Sheet4!D102 | F4: =Sheet4!E102 | G4: =Sheet4!F102 | H4: =Sheet4!G102 | I4: 0 | K4: 0 | L4: =Sheet4!H102
A5: 4 | B5: KwaZulu-Natal | C5: =Sheet4!B161 | D5: 0 | E5: =Sheet4!D161 | F5: =Sheet4!E161 | G5: =Sheet4!F161 | H5: =Sheet4!G161 | I5: 0 | K5: 0 | L5: =Sheet4!H161
A6: 5 | B6: Limpopo | C6: =Sheet4!B189 | D6: 0 | E6: =Sheet4!D189 | F6: =Sheet4!E189 | G6: =Sheet4!F189 | H6: =Sheet4!G189 | I6: 0 | K6: 0 | L6: =Sheet4!H189
A7: 6 | B7: Mpumalanga | C7: =Sheet4!B210 | D7: 0 | E7: =Sheet4!D210 | F7: =Sheet4!E210 | G7: =Sheet4!F210 | H7: =Sheet4!G210 | I7: 0 | K7: 0 | L7: =Sheet4!H210
A8: 7 | B8: North West | C8: =Sheet4!B231 | D8: 0 | E8: =Sheet4!D231 | F8: =Sheet4!E231 | G8: =Sheet4!F231 | H8: =Sheet4!G231 | I8: 0 | K8: 0 | L8: =Sheet4!H231
A9: 8 | B9: Northern Cape | C9: =Sheet4!B253 | D9: 0 | E9: =Sheet4!D253 | F9: =Sheet4!E253 | G9: =Sheet4!F253 | H9: =Sheet4!G253 | I9: 0 | K9: 0 | L9: =Sheet4!H253
A10: 9 | B10: Western Cape | C10: =Sheet4!B288 | D10: 0 | E10: =Sheet4!D288 | F10: =Sheet4!E288 | G10: =Sheet4!F288 | H10: =Sheet4!G288 | I10: 0 | K10: 0 | L10: =Sheet4!H288
B11: TOTAL | C11: =SUM(C2:C10) | D11: =SUM(D2:D10) | E11: =SUM(E2:E10) | F11: =SUM(F2:F10) | G11: =SUM(G2:G10) | H11: =SUM(H2:H10) | I11: =SUM(I2:I10) | K11: =SUM(K2:K10) | L11: =Sheet4!H289
