Workbook

Sheet Sheet4
A1: MUNICIPALITY/ DISTRICTS | B1: NUMBER OF IEC WARDS | D1: NUMBER OF BRANCHES CONVENED | E1: NUMBER OF BRANCHES NOT CONVENED | F1: NUMBER OF BRANCHES PASSED AUDIT | G1: NUMBER OF BRANCHES FAILED AUDIT | H1: PERCENTAGE % TOWARDS BPA/BGA
A2: BUF-Duncan Village | B2: 8 | D2: =SUM(F2:G2) -> 8 | E2: =B2-D2 -> 0 | F2: 3 | G2: 5 | H2: =F2/B2 -> 0.375
A3: BUF-East London | B3: 17 | D3: 14 | E3: =B3-D3 -> 3 | F3: 16 | G3: 0 | H3: =F3/B3 -> 0.94117647
A4: BUF-King Williams Town | B4: 13 | D4: 6 | E4: =B4-D4 -> 7 | F4: 5 | G4: 3 | H4: =F4/B4 -> 0.38461538
A5: BUF-Mdantsane | B5: 12 | D5: 12 | E5: =B5-D5 -> 0 | F5: 6 | G5: 4 | H5: =F5/B5 -> 0.5
A6: TOTAL | B6: =SUM(B2:B5) -> 50 | D6: =SUM(D2:D5) -> 40 | E6: =SUM(E2:E5) -> 10 | F6: =SUM(F2:F5) -> 30 | G6: =SUM(G2:G5) -> 12 | H6: =F6/B6 -> 0.6
A7: Dr. Beyers Naude / Blue Crane Route | B7: 12 + 6 = 18 | C7: 18 | D7: 2 | E7: =C7-D7 -> 16 | F7: 1 | G7: 1 | H7: =F7/C7 -> 0.055555556
A8: Kouga / Kou-Kamma | B8: 15 + 6 = 21 | C8: 21 | D8: =SUM(F8:G8) -> 1 | E8: =C8-D8 -> 20 | F8: 1 | G8: 0 | H8: =F8/C8 -> 0.047619048
A9: Makana | B9: 14 | D9: 3 | E9: =B9-D9 -> 11 | F9: 0 | G9: 3 | H9: =F9/B9 -> 0
A10: Ndlambe | B10: 10 | D10: 3 | E10: =B10-D10 -> 7 | F10: 2 | G10: 1 | H10: =F10/B10 -> 0.2
A11: Sundays River Valley | B11: 8 | D11: 2 | E11: =B11-D11 -> 6 | F11: 0 | G11: 2 | H11: =F11/B11 -> 0
A12: TOTAL | B12: =14+10+8+18+21 -> 71 | D12: =SUM(D7:D11) -> 11 | E12: =SUM(E7:E11) -> 60 | F12: =SUM(F7:F11) -> 4 | G12: =SUM(G7:G11) -> 7 | H12: =F12/B12 -> 0.056338028
A13: Amahlathi / Great Kei | B13: 15 + 7 = 22 | C13: 22 | D13: =SUM(F13:G13) -> 4 | E13: =C13-D13 -> 18 | F13: 4 | G13: 0 | H13: =F13/C13 -> 0.18181818
A14: Mbashe | B14: 32 | D14: =SUM(F14:G14) -> 6 | E14: =B14-D14 -> 26 | F14: 1 | G14: 5 | H14: =F14/B14 -> 0.03125
A15: Mnquma | B15: 32 | D15: =SUM(F15:G15) -> 5 | E15: =B15-D15 -> 27 | F15: 2 | G15: 3 | H15: =F15/B15 -> 0.0625
A16: Ngqushwa | B16: 12 | D16: =SUM(F16:G16) -> 2 | E16: =B16-D16 -> 10 | F16: 2 | G16: 0 | H16: =F16/B16 -> 0.16666667
A17: Raymond Mhlaba | B17: 23 | D17: =SUM(F17:G17) -> 4 | E17: =B17-D17 -> 19 | F17: 3 | G17: 1 | H17: =F17/B17 -> 0.13043478
A18: TOTAL | B18: =22+32+32+12+23 -> 121 | C18: =22+32+32+12+23 -> 121 | D18: =SUM(D13:D17) -> 21 | E18: =SUM(E13:E17) -> 100 | F18: =SUM(F13:F17) -> 12 | G18: =SUM(G13:G17) -> 9 | H18: =F18/B18 -> 0.099173554
A19: Inxuba Yethemba | B19: 9 | D19: =SUM(F19:G19) -> 0 | E19: =B19-D19 -> 9 | F19: 0 | G19: 0 | H19: =F19/B19 -> 0
A20: Intsika Yethu | B20: 21 | D20: =SUM(F20:G20) -> 7 | E20: =B20-D20 -> 14 | F20: 5 | G20: 2 | H20: =F20/B20 -> 0.23809524
A21: Emalahleni | B21: 17 | D21: =SUM(F21:G21) -> 2 | E21: =B21-D21 -> 15 | F21: 1 | G21: 1 | H21: =F21/B21 -> 0.058823529
A22: Dr AB Xuma | B22: 20 | D22: 3 | E22: =B22-D22 -> 17 | F22: 3 | G22: 3 | H22: =F22/B22 -> 0.15
A23: Sakhisizwe | B23: 9 | D23: =SUM(F23:G23) -> 0 | E23: =B23-D23 -> 9 | F23: 0 | G23: 0 | H23: =F23/B23 -> 0
A24: Enoch Mgijima | B24: 34 | D24: 3 | E24: =B24-D24 -> 31 | F24: 3 | G24: 1 | H24: =F24/B24 -> 0.088235294
A25: TOTAL | B25: =SUM(B19:B24) -> 110 | D25: =SUM(D19:D24) -> 15 | E25: =SUM(E19:E24) -> 95 | F25: =SUM(F19:F24) -> 12 | G25: =SUM(G19:G24) -> 7 | H25: =F25/B25 -> 0.10909091
A26: Elundini | B26: 17 | D26: =SUM(F26:G26) -> 2 | E26: =B26-D26 -> 15 | F26: 0 | G26: 2 | H26: =F26/B26 -> 0
A27: Senqu | B27: 17 | D27: 4 | E27: =B27-D27 -> 13 | F27: 4 | G27: 0 | H27: =F27/B27 -> 0.23529412
A28: Walter Sisulu | B28: 11 | D28: 5 | E28: =B28-D28 -> 6 | F28: 3 | G28: 2 | H28: =F28/B28 -> 0.27272727
A29: TOTAL | B29: =SUM(B26:B28) -> 45 | D29: =SUM(D26:D28) -> 11 | E29: =SUM(E26:E28) -> 34 | F29: =SUM(F26:F28) -> 7 | G29: =SUM(G26:G28) -> 4 | H29: =F29/B29 -> 0.15555556
A30: Ngquza Hill | B30: 32 | D30: 7 | E30: =B30-D30 -> 25 | F30: 1 | G30: 6 | H30: =F30/B30 -> 0.03125
A31: Port St Johns | B31: 20 | D31: =SUM(F31:G31) -> 3 | E31: =B31-D31 -> 17 | F31: 1 | G31: 2 | H31: =F31/B31 -> 0.05
A32: Mhlontlo | B32: 26 | D32: 6 | E32: =B32-D32 -> 20 | F32: 3 | G32: 5 | H32: =F32/B32 -> 0.11538462
A33: King Sabata Dalindyebo | B33: 37 | D33: =SUM(F33:G33) -> 13 | E33: =B33-D33 -> 24 | F33: 6 | G33: 7 | H33: =F33/B33 -> 0.16216216
A34: Nyandeni | B34: 32 | D34: 10 | E34: =B34-D34 -> 22 | F34: 9 | G34: 8 | H34: =F34/B34 -> 0.28125
A35: TOTAL | B35: =SUM(B30:B34) -> 147 | D35: =SUM(D30:D34) -> 39 | E35: =SUM(E30:E34) -> 108 | F35: =SUM(F30:F34) -> 20 | G35: =SUM(G30:G34) -> 28 | H35: =F35/B35 -> 0.13605442
A36: Matatiele | B36: 27 | D36: 9 | E36: =B36-D36 -> 18 | F36: 2 | G36: 5 | H36: =F36/B36 -> 0.074074074
A37: Umzimvubu | B37: 28 | D37: 6 | E37: =B37-D37 -> 22 | F37: 0 | G37: 6 | H37: =F37/B37 -> 0
A38: Winnie Madikizela Mandela | B38: 32 | D38: 5 | E38: =B38-D38 -> 27 | F38: 2 | G38: 3 | H38: =F38/B38 -> 0.0625
A39: Ntabankulu | B39: 19 | D39: 5 | E39: =B39-D39 -> 14 | F39: 1 | G39: 4 | H39: =F39/B39 -> 0.052631579
A40: TOTAL | B40: =SUM(B36:B39) -> 106 | D40: =SUM(D36:D39) -> 25 | E40: =SUM(E36:E39) -> 81 | F40: =SUM(F36:F39) -> 5 | G40: =SUM(G36:G39) -> 18 | H40: =F40/B40 -> 0.047169811
...

Sheet Sheet1
A1: PROVINCE | B1: NUMBER OF IEC WARDS | C1: TOTAL NUMBER OF REGISTERS ISSUED | D1: NUMBER OF BRANCHES CONVENED BPA/BGA | E1: NUMBER OF BRANCHES NOT CONVENED BPA/BGA | F1: NUMBER OF BRANCHES PASSED FINAL AUDIT TO THE 1ST SRPA | G1: NUMBER OF BRANCHES FAILED AUDIT FINAL AUDIT TO THE 1ST SRPA | H1: NUMBER OF BRANCHES CURRENTLY IN AUDIT | I1: PERCENTAGE % TOWARDS 1ST SRPA
A2: EASTERN CAPE | B2: 710 | C2: 316 | D2: 223 | E2: =Sheet4!E48:H48 -> 501 | F2: =Sheet4!F48 -> 127 | G2: =Sheet4!G48 -> 98 | H2: =D2-F2-G2 -> -2 | I2: =F2/B2 -> 0.17887324
A3: FREE STATE | B3: 319 | C3: 239 | D3: 205 | E3: =Sheet4!E72 -> 105 | F3: =Sheet4!F72 -> 169 | G3: =Sheet4!G72 -> 45 | H3: =D3-F3-G3 -> -9 | I3: =F3/B3 -> 0.52978056
A4: GAUTENG | B4: 529 | C4: 509 | D4: 502 | E4: =Sheet4!E101 -> 25 | F4: =Sheet4!F101 -> 476 | G4: =Sheet4!G101 -> 28 | H4: =D4-F4-G4 -> -2 | I4: =F4/B4 -> 0.89981096
A5: KWAZULU NATAL | B5: 901 | C5: 282 | D5: 170 | E5: =Sheet4!E160 -> 739 | F5: =Sheet4!F160 -> 79 | G5: =Sheet4!G160 -> 83 | H5: =D5-F5-G5 -> 8 | I5: =F5/B5 -> 0.087680355
A6: LIMPOPO | B6: 568 | C6: 438 | D6: 375 | E6: =Sheet4!E188 -> 189 | F6: =Sheet4!F188 -> 325 | G6: =Sheet4!G188 -> 54 | H6: =D6-F6-G6 -> -4 | I6: =F6/B6 -> 0.5721831
A7: MPUMALANGA | B7: 400 | C7: 345 | D7: 315 | E7: =Sheet4!E209 -> 76 | F7: =Sheet4!F209 -> 278 | G7: =Sheet4!G209 -> 46 | H7: =D7-F7-G7 -> -9 | I7: =F7/B7 -> 0.695
A8: NORTH WEST | B8: 403 | C8: 270 | D8: 204 | E8: =Sheet4!E230 -> 195 | F8: =Sheet4!F230 -> 175 | G8: =Sheet4!G230 -> 33 | H8: =D8-F8-G8 -> -4 | I8: =F8/B8 -> 0.43424318
A9: NORTHERN CAPE | B9: 239 | C9: 96 | D9: 75 | E9: =Sheet4!E252 -> 162 | F9: =Sheet4!F252 -> 52 | G9: =Sheet4!G252 -> 25 | H9: =D9-F9-G9 -> -2 | I9: =F9/B9 -> 0.21757322
A10: WESTERN CAPE | B10: 399 | C10: 175 | D10: 67 | E10: =Sheet4!E286 -> 326 | F10: =Sheet4!F286 -> 53 | G10: =Sheet4!G286 -> 20 | H10: =D10-F10-G10 -> -6 | I10: =F10/B10 -> 0.13283208
A11: TOTAL | B11: =SUM(B2:B10) -> 4468 | C11: =SUM(C2:C10) -> 2670 | D11: =SUM(D2:D10) -> 2136 | F11: =SUM(F2:F10) -> 1734 | G11: =SUM(G2:G10) -> 432 | H11: =SUM(H2:H10) -> -30 | I11: =F11/B11 -> 0.38809311
