Workbook

Sheet SHEET 2
A1: # | B1: PROVINCE | C1: NUMBER OF WARDS | D1: TOTAL NUMBER OF WARDS WITH 200 OR MORE VALID MEMBERSHIP | E1: TOTAL NUMBER OF WARDS WITH LESS THAN 200 VALID MEMBERSHIP | F1: PERCENTAGE % TOWARDS SRPA
A2: 1. | B2: Eastern Cape | C2: =Sheet1!B48 -> 710 | D2: =Sheet1!D48 -> 297 | E2: =Sheet1!E48 -> 413 | F2: =D2/C2 -> 0.41830986
A3: 2. | B3: Free State | C3: =Sheet1!B72 -> 319 | D3: =Sheet1!D72 -> 251 | E3: =Sheet1!E72 -> 68 | F3: =D3/C3 -> 0.78683386
A4: 3. | B4: Gauteng | C4: =Sheet1!B101 -> 529 | D4: =Sheet1!D101 -> 509 | E4: =Sheet1!E101 -> 20 | F4: =D4/C4 -> 0.96219282
A5: 4. | B5: KwaZulu-Natal | C5: =Sheet1!B160 -> 901 | D5: =Sheet1!D160 -> 265 | E5: =Sheet1!E160 -> 636 | F5: =D5/C5 -> 0.29411765
A6: 5. | B6: Limpopo | C6: =Sheet1!B188 -> 568 | D6: =Sheet1!D188 -> 450 | E6: =Sheet1!E188 -> 118 | F6: =D6/C6 -> 0.79225352
A7: 6. | B7: Mpumalanga | C7: =Sheet1!B209 -> 400 | D7: =Sheet1!D209 -> 358 | E7: =Sheet1!E209 -> 42 | F7: =D7/C7 -> 0.895
A8: 7. | B8: North West | C8: =Sheet1!B230 -> 403 | D8: =Sheet1!D230 -> 275 | E8: =Sheet1!E230 -> 128 | F8: =D8/C8 -> 0.68238213
A9: 8. | B9: Northern Cape | C9: =Sheet1!B252 -> 239 | D9: =Sheet1!D252 -> 98 | E9: =Sheet1!E252 -> 141 | F9: =D9/C9 -> 0.41004184
A10: 9. | B10: Western Cape | C10: =Sheet1!B286 -> 399 | D10: =Sheet1!D286 -> 171 | E10: =Sheet1!E286 -> 228 | F10: =D10/C10 -> 0.42857143
A11: TOTAL | C11: =SUM(C2:C10) -> 4468 | D11: =SUM(D2:D10) -> 2674 | E11: =SUM(E2:E10) -> 1794 | F11: =D11/C11 -> 0.59847807
A15: # | B15: PROVINCE | C15: NUMBER OF WARDS | D15: TOTAL NUMBER OF WARDS WITH 200 OR MORE VALID MEMBERSHIP | E15: TOTAL NUMBER OF WARDS WITH LESS THAN 200 VALID MEMBERSHIP | F15: PERCENTAGE %
A16: 1. | B16: Eastern Cape | C16: 710 | D16: 266 | E16: =C16-D16 -> 444 | F16: =D16/C16 -> 0.37464789
A17: 2. | B17: Free State | C17: 319 | D17: 210 | E17: =C17-D17 -> 109 | F17: =D17/C17 -> 0.65830721
A18: 3. | B18: Gauteng | C18: 529 | D18: 475 | E18: =C18-D18 -> 54 | F18: =D18/C18 -> 0.8979206
A19: 4. | B19: KwaZulu-Natal | C19: 901 | D19: 253 | E19: =C19-D19 -> 648 | F19: =D19/C19 -> 0.28079911
A20: 5. | B20: Limpopo | C20: 568 | D20: 302 | E20: =C20-D20 -> 266 | F20: =D20/C20 -> 0.53169014
A21: 6. | B21: Mpumalanga | C21: 400 | D21: 327 | E21: =C21-D21 -> 73 | F21: =D21/C21 -> 0.8175
A22: 7. | B22: North West | C22: 403 | D22: 222 | E22: =C22-D22 -> 181 | F22: =D22/C22 -> 0.55086849
A23: 8. | B23: Northern Cape | C23: 239 | D23: 72 | E23: =C23-D23 -> 167 | F23: =D23/C23 -> 0.30125523
A24: 9. | B24: Western Cape | C24: 399 | D24: 152 | E24: =C24-D24 -> 247 | F24: =D24/C24 -> 0.38095238
A25: TOTAL | C25: =SUM(C16:C24) -> 4468 | D25: =SUM(D16:D24) -> 2279 | E25: =SUM(E16:E24) -> 2189 | F25: =D25/C25 -> 0.51007162

Sheet Sheet1
A1: MUNICIPALITY/ DISTRICTS | B1: NUMBER OF IEC WARDS | D1: TOTAL NUMBER OF WARDS WITH 200 OR MORE VALID MEMBERSHIP | E1: TOTAL NUMBER OF WARDS WITH LESS THAN 200 VALID MEMBERSHIP | F1: PERCENTAGE % TOWARDS BPA/BGA | G1: DEPLOYEE
A2: BUF-Duncan Village | B2: 8 | D2: 8 | E2: =B2-D2 -> 0 | F2: =D2/B2 -> 1
A3: BUF-East London | B3: 17 | D3: 16 | E3: =B3-D3 -> 1 | F3: =D3/B3 -> 0.94117647
A4: BUF-King Williams Town | B4: 13 | D4: 11 | E4: =B4-D4 -> 2 | F4: =D4/B4 -> 0.84615385
A5: BUF-Mdantsane | B5: 12 | D5: 12 | E5: =B5-D5 -> 0 | F5: =D5/B5 -> 1
A6: TOTAL | B6: =SUM(B2:B5) -> 50 | D6: =SUM(D2:D5) -> 47 | E6: =SUM(E2:E5) -> 3 | F6: =D6/B6 -> 0.94
A7: Dr. Beyers Naude / Blue Crane Route | B7: 12 + 6 = 18 | C7: 18 | D7: 2 | E7: =C7-D7 -> 16 | F7: =D7/C7 -> 0.11111111
A8: Kouga / Kou-Kamma | B8: 15 + 6 = 21 | C8: 21 | D8: 2 | E8: =C8-D8 -> 19 | F8: =D8/C8 -> 0.095238095
A9: Makana | B9: 14 | D9: 4 | E9: =B9-D9 -> 10 | F9: =D9/B9 -> 0.28571429
A10: Ndlambe | B10: 10 | D10: 1 | E10: =B10-D10 -> 9 | F10: =D10/B10 -> 0.1
A11: Sundays River Valley | B11: 8 | D11: 2 | E11: =B11-D11 -> 6 | F11: =D11/B11 -> 0.25
A12: TOTAL | B12: =14+10+8+18+21 -> 71 | D12: =SUM(D7:D11) -> 11 | E12: =SUM(E7:E11) -> 60 | F12: =D12/B12 -> 0.15492958
A13: Amahlathi / Great Kei | B13: 15 + 7 = 22 | C13: 22 | D13: 9 | E13: =C13-D13 -> 13 | F13: =D13/C13 -> 0.40909091
A14: Mbashe | B14: 32 | D14: 8 | E14: =B14-D14 -> 24 | F14: =D14/B14 -> 0.25
A15: Mnquma | B15: 32 | D15: 3 | E15: =B15-D15 -> 29 | F15: =D15/B15 -> 0.09375
A16: Ngqushwa | B16: 12 | D16: 3 | E16: =B16-D16 -> 9 | F16: =D16/B16 -> 0.25
A17: Raymond Mhlaba | B17: 23 | D17: 4 | E17: =B17-D17 -> 19 | F17: =D17/B17 -> 0.17391304
A18: TOTAL | B18: =22+32+32+12+23 -> 121 | D18: =SUM(D13:D17) -> 27 | E18: =SUM(E13:E17) -> 94 | F18: =D18/B18 -> 0.2231405
A19: Inxuba Yethemba | B19: 9 | D19: 1 | E19: =B19-D19 -> 8 | F19: =D19/B19 -> 0.11111111
A20: Intsika Yethu | B20: 21 | D20: 9 | E20: =B20-D20 -> 12 | F20: =D20/B20 -> 0.42857143
A21: Emalahleni | B21: 17 | D21: 2 | E21: =B21-D21 -> 15 | F21: =D21/B21 -> 0.11764706
A22: Dr AB Xuma | B22: 20 | D22: 6 | E22: =B22-D22 -> 14 | F22: =D22/B22 -> 0.3
A23: Sakhisizwe | B23: 9 | D23: 2 | E23: =B23-D23 -> 7 | F23: =D23/B23 -> 0.22222222
A24: Enoch Mgijima | B24: 34 | D24: 11 | E24: =B24-D24 -> 23 | F24: =D24/B24 -> 0.32352941
A25: TOTAL | B25: =SUM(B19:B24) -> 110 | D25: =SUM(D19:D24) -> 31 | E25: =SUM(E19:E24) -> 79 | F25: =D25/B25 -> 0.28181818
A26: Elundini | B26: 17 | D26: 1 | E26: =B26-D26 -> 16 | F26: =D26/B26 -> 0.058823529
A27: Senqu | B27: 17 | D27: 6 | E27: =B27-D27 -> 11 | F27: =D27/B27 -> 0.35294118
A28: Walter Sisulu | B28: 11 | D28: 4 | E28: =B28-D28 -> 7 | F28: =D28/B28 -> 0.36363636
A29: TOTAL | B29: =SUM(B26:B28) -> 45 | D29: =SUM(D26:D28) -> 11 | E29: =SUM(E26:E28) -> 34 | F29: =D29/B29 -> 0.24444444
A30: Ngquza Hill | B30: 32 | D30: 11 | E30: =B30-D30 -> 21 | F30: =D30/B30 -> 0.34375
A31: Port St Johns | B31: 20 | D31: 9 | E31: =B31-D31 -> 11 | F31: =D31/B31 -> 0.45
A32: Mhlontlo | B32: 26 | D32: 16 | E32: =B32-D32 -> 10 | F32: =D32/B32 -> 0.61538462
A33: King Sabata Dalindyebo | B33: 37 | D33: 27 | E33: =B33-D33 -> 10 | F33: =D33/B33 -> 0.72972973
A34: Nyandeni | B34: 32 | D34: 20 | E34: =B34-D34 -> 12 | F34: =D34/B34 -> 0.625
A35: TOTAL | B35: =SUM(B30:B34) -> 147 | D35: =SUM(D30:D34) -> 83 | E35: =SUM(E30:E34) -> 64 | F35: =D35/B35 -> 0.56462585
A36: Matatiele | B36: 27 | D36: 9 | E36: =B36-D36 -> 18 | F36: =D36/B36 -> 0.33333333
A37: Umzimvubu | B37: 28 | D37: 11 | E37: =B37-D37 -> 17 | F37: =D37/B37 -> 0.39285714
A38: Winnie Madikizela Mandela | B38: 32 | D38: 6 | E38: =B38-D38 -> 26 | F38: =D38/B38 -> 0.1875
A39: Ntabankulu | B39: 19 | D39: 8 | E39: =B39-D39 -> 11 | F39: =D39/B39 -> 0.42105263
A40: TOTAL | B40: =SUM(B36:B39) -> 106 | D40: =SUM(D36:D39) -> 34 | E40: =SUM(E36:E39) -> 72 | F40: =D40/B40 -> 0.32075472
...

Sheet Sheet3
A1: MUNICIPALITY | B1: NUMBER OF IEC WARDS | C1: TOTAL NUMBER OF WARDS WITH 200 OR MORE VALID MEMBERSHIP | D1: TOTAL NUMBER OF WARDS WITH LESS THAN 200 VALID MEMBERSHIP | E1: PERCENTAGE % TOWARDS BPA/BGA
A2: Kou-Kamma | B2: 6 | C2: 0 | D2: =B2-C2 -> 6 | E2: 0
A3: Inxuba Yethemba | B3: 9 | C3: 1 | D3: =B3-C3 -> 8 | E3: 0.11
A4: EASTERN CAPE | B4: =SUM(B2:B3) -> 15 | C4: =SUM(C2:C3) -> 1 | D4: =SUM(D2:D3) -> 14 | E4: 0.22
A5: Umvoti | B5: 14 | C5: 1 | D5: =B5-C5 -> 13 | E5: 0.07
A6: KWA-ZULU NATAL | B6: 14 | C6: 1 | D6: 13 | E6: 0.07
A7: Umsombomvu / Beaufort West | B7: 7 + 7 = 14 | C7: 3 | D7: =14-C7 -> 11 | E7: 0.21
A8: NORTHERN CAPE | B8: 14 | C8: 3 | D8: 11 | E8: 0.21
A9: Bergrivier / Cederberg | B9: 7 + 6 = 13 | C9: 1 | D9: =13-C9 -> 12 | E9: 0.08
A10: Cape Agulhas / Swellendam | B10: 6 + 6 = 12 | C10: 2 | D10: =12-C10 -> 10 | E10: 0.17
A11: Langeberg / Laingsburg | B11: 12 + 4 = 16 | C11: 4 | D11: =16-4 -> 12 | E11: 0.25
A12: Hessequa | B12: 9 | C12: 1 | D12: =B12-C12 -> 8 | E12: 0.11
A13: Mossel Bay | B13: 15 | C13: 3 | D13: =B13-3 -> 12 | E13: 0.2
A14: Oudtshoorn / Prince Albert | B14: 13 + 4 =17 | C14: 1 | D14: =17-C14 -> 16 | E14: 0.06
A15: WESTERN CAPE | B15: =13+12+16+9+15+17 -> 82 | C15: =SUM(C9:C14) -> 12 | D15: =SUM(D9:D14) -> 70 | E15: 0.15
A16: TOTAL | B16: =SUM(B4,B6,B8,B15) -> 125 | C16: =SUM(C4,C6,C8,C15) -> 17 | D16: =SUM(D4,D6,D8,D15) -> 108 | E16: =C16/B16 -> 0.136

Sheet Sheet2
A1: # | B1: Province | C1: Region | D1: Municipality | E1: Ward | F1: Valid Membership | G1: BGA/BPA
A2: 1 | B2: Eastern Cape | C2: Alfred Nzo | D2: Matatiele | E2: 24401003 | F2: 203 | G2: BPA
A3: 2 | B3: Eastern Cape | C3: Alfred Nzo | D3: Matatiele | E3: 24401015 | F3: 203 | G3: BGA
A4: 3 | B4: Eastern Cape | C4: Alfred Nzo | D4: Matatiele | E4: 24401020 | F4: 203 | G4: BGA
A5: 4 | B5: Eastern Cape | C5: Alfred Nzo | D5: Matatiele | E5: 24401024 | F5: 218 | G5: BGA
A6: 5 | B6: Eastern Cape | C6: Alfred Nzo | D6: Matatiele | E6: 24401025 | F6: 208 | G6: BGA
A7: 6 | B7: Eastern Cape | C7: Alfred Nzo | D7: Ntabankulu | E7: 24404004 | F7: 209 | G7: BPA
A8: 7 | B8: Eastern Cape | C8: Alfred Nzo | D8: Ntabankulu | E8: 24404007 | F8: 203 | G8: BGA
A9: 8 | B9: Eastern Cape | C9: Alfred Nzo | D9: Ntabankulu | E9: 24404010 | F9: 207 | G9: BGA
A10: 9 | B10: Eastern Cape | C10: Alfred Nzo | D10: Ntabankulu | E10: 24404012 | F10: 201 | G10: BGA
A11: 10 | B11: Eastern Cape | C11: Alfred Nzo | D11: Umzimvubu | E11: 24402017 | F11: 215 | G11: BGA
A12: 11 | B12: Eastern Cape | C12: Alfred Nzo | D12: Umzimvubu | E12: 24402023 | F12: 202 | G12: BGA
A13: 12 | B13: Eastern Cape | C13: Alfred Nzo | D13: Umzimvubu | E13: 24402026 | F13: 200 | G13: BGA
... A1039: 1038 | B1039: Western Cape | C1039: Souuthern Cape | D1039: George | E1039: 10404027 | F1039: 202 | G1039: BGA
